Workbook
Name metal_type2_list: metal_type2[metal_type2]
Name platinum_list: platinum[platinum]
Name silver_list: silver[silver]
Name vendor_name2_list: vendor_name2[vendor_name2]

Sheet source
B2: Diaspark_Vendor | C2: Diaspark | D2: Vendor code | E2: Codes | F2: Vendor_Name | H2: vendor_name2 | J2: ship_nm | K2: ship_contact_nm | L2: ship_address1 | M2: ship_address2 | N2: ship_city | O2: ship_state | P2: ship_country | Q2: ship_zip | R2: ship_phone | S2: ship_fax
B3: =portal_vendor_code[[#This Row],[Diaspark]]&portal_vendor_code[[#This Row],[Vendor code ]] -> CPCP-E00101 | C3: CP | D3: CP-E00101 | E3: 1 | H3: ELEGANT COLLECTION | J3: ELEGANT COLLECTION | K3: PRASAD RAUT | L3: PLOT NO: 56/A | M3: SEEPZ-SEZ, ANDHERI - EAST | N3: MUMBAI | O3: MAHARASHTRA | P3: INDIA | Q3: 400096 | R3: +91 (22) 6640 0909
B4: =portal_vendor_code[[#This Row],[Diaspark]]&portal_vendor_code[[#This Row],[Vendor code ]] -> KSDSD-UDE034 | C4: KSD | D4: SD-UDE034 | E4: 1 | H4: JEWEL ONE | J4: JEWEL ONE | K4: SARIKA NAMBIAR | L4: PLOT NO: 164, ROAD NO: 4, SURAT-SEZ | M4: NEAR SACHIN RAILWAY STATION | N4: SURAT | O4: GUJARAT | P4: INDIA | Q4: 394230 | R4: +91 (261) 6111 333
B5: =portal_vendor_code[[#This Row],[Diaspark]]&portal_vendor_code[[#This Row],[Vendor code ]] -> LGSD-UDE034 | C5: LG | D5: SD-UDE034 | E5: 1 | H5: KAMA JEWELRY PVT. LTD. | J5: KAMA JEWELRY PVT. LTD. | K5: APARNA CHAUGHULE | L5: UNIT-II, 601-604, MULTISTORIED BUILDING | M5: SEEPZ-SEZ, ANDHERI - EAST | N5: MUMBAI | O5: MAHARASHTRA | P5: INDIA | Q5: 400096 | R5: +91 (22) 4344 1000
B6: =portal_vendor_code[[#This Row],[Diaspark]]&portal_vendor_code[[#This Row],[Vendor code ]] -> CPCP-J00301 | C6: CP | D6: CP-J00301 | E6: 2 | H6: KAMA JEWELRY PVT LTD | J6: KAMA JEWELRY PVT LTD | K6: APARNA CHAUGHULE | L6: UNIT-II, 601-604, MULTISTORIED BUILDING | M6: SEEPZ-SEZ, ANDHERI - EAST | N6: MUMBAI | O6: MAHARASHTRA | P6: INDIA | Q6: 400096 | R6: +91 (22) 4344 1000
B7: =portal_vendor_code[[#This Row],[Diaspark]]&portal_vendor_code[[#This Row],[Vendor code ]] -> KSDJ210 | C7: KSD | D7: J210 | E7: 2 | H7: KIRAN JEWELRY | J7: KIRAN JEWELRY | K7: RANJEET GUPTA | L7: PLOT NO: 28, 59/60, SURAT-SEZ | M7: NEAR SACHIN RAILWAY STATION | N7: SURAT | O7: GUJARAT | P7: INDIA | Q7: 394230 | R7: +91 (261) 6111 200
B8: =portal_vendor_code[[#This Row],[Diaspark]]&portal_vendor_code[[#This Row],[Vendor code ]] -> LGLG-J004 | C8: LG | D8: LG-J004 | E8: 2 | H8: SELECT VENDOR
B9: =portal_vendor_code[[#This Row],[Diaspark]]&portal_vendor_code[[#This Row],[Vendor code ]] -> CPCP-K00102 | C9: CP | D9: CP-K00102 | E9: 3
B10: =portal_vendor_code[[#This Row],[Diaspark]]&portal_vendor_code[[#This Row],[Vendor code ]] -> KSDSD-K016 | C10: KSD | D10: SD-K016 | E10: 3
B11: =portal_vendor_code[[#This Row],[Diaspark]]&portal_vendor_code[[#This Row],[Vendor code ]] -> KSDSD-K017 | C11: KSD | D11: SD-K017 | E11: 3
B12: =portal_vendor_code[[#This Row],[Diaspark]]&portal_vendor_code[[#This Row],[Vendor code ]] -> LGLG-K003 | C12: LG | D12: LG-K003 | E12: 3
B13: =portal_vendor_code[[#This Row],[Diaspark]]&portal_vendor_code[[#This Row],[Vendor code ]] -> LGLG-K005 | C13: LG | D13: LG-K005 | E13: 3
B14: =portal_vendor_code[[#This Row],[Diaspark]]&portal_vendor_code[[#This Row],[Vendor code ]] -> CPCP-K00104 | C14: CP | D14: CP-K00104 | E14: 4
B15: =portal_vendor_code[[#This Row],[Diaspark]]&portal_vendor_code[[#This Row],[Vendor code ]] -> KSDK069 | C15: KSD | D15: K069 | E15: 4
B16: =portal_vendor_code[[#This Row],[Diaspark]]&portal_vendor_code[[#This Row],[Vendor code ]] -> LGLG-K013 | C16: LG | D16: LG-K013 | E16: 4 | H16: metal_type2 | J16: metal_type | K16: metal | L16: description | M16: metal_purity | N16: gram_per_ounce | O16: pg_divisor | P16: metal_rate | Q16: rate_purity | R16: metal_rate_per_gram
B17: =portal_vendor_code[[#This Row],[Diaspark]]&portal_vendor_code[[#This Row],[Vendor code ]] -> CPCP-K00101 | C17: CP | D17: CP-K00101 | E17: 5 | H17: 9KT | J17: 9KT | K17: GOLD | L17: =IF(metal_type[[#This Row],[metal]]="SILVER", "STERLING SILVER CASTING", IF(metal_type[[#This Row],[metal]]="SILVER - 925", "STERLING SILVER CASTING", IF(metal_type[[#This Row],[metal]]="PLATINUM", "950 PLATINUM CASTING", IF(metal_type[[#This Row],[metal_type]]="9KT", "9KT GOLD CASTING", IF(metal_type[[#This Row],[metal_type]]="10KT", "10KT GOLD CASTING", IF(metal_type[[#This Row],[metal_type]]="14KT", "14KT GOLD CASTING", IF(metal_type[[#This Row],[metal_type]]="18KT", "18KT GOLD CASTING", IF(metal_type[[#This Row],[metal_type]]="22KT", "22KT GOLD CASTING", IF(metal_type[[#This Row],[metal_type]]="24KT", "GOLD CASTING", ""))))))))) -> 9KT GOLD CASTING | M17: 0.375 | N17: 31.1035 | O17: 0.995 | P17: =IF(metal_type[[#This Row],[metal]]="GOLD",Sheet1!$O$12,IF(metal_type[[#This Row],[metal]]="PLATINUM",Sheet1!$O$13,IF(metal_type[[#This Row],[metal]]="SILVER",Sheet1!$O$14,IF(metal_type[[#This Row],[metal]]="SILVER - 925",Sheet1!$O$14,"")))) -> 0 | Q17: 0.375 | R17: =(metal_type[[#This Row],[metal_rate]]/metal_type[[#This Row],[gram_per_ounce]])*metal_type[[#This Row],[rate_purity]] -> 0
B18: =portal_vendor_code[[#This Row],[Diaspark]]&portal_vendor_code[[#This Row],[Vendor code ]] -> KSDSD-UDK024 | C18: KSD | D18: SD-UDK024 | E18: 5 | H18: 10KT | J18: 10KT | K18: GOLD | L18: =IF(metal_type[[#This Row],[metal]]="SILVER", "STERLING SILVER CASTING", IF(metal_type[[#This Row],[metal]]="SILVER - 925", "STERLING SILVER CASTING", IF(metal_type[[#This Row],[metal]]="PLATINUM", "950 PLATINUM CASTING", IF(metal_type[[#This Row],[metal_type]]="9KT", "9KT GOLD CASTING", IF(metal_type[[#This Row],[metal_type]]="10KT", "10KT GOLD CASTING", IF(metal_type[[#This Row],[metal_type]]="14KT", "14KT GOLD CASTING", IF(metal_type[[#This Row],[metal_type]]="18KT", "18KT GOLD CASTING", IF(metal_type[[#This Row],[metal_type]]="22KT", "22KT GOLD CASTING", IF(metal_type[[#This Row],[metal_type]]="24KT", "GOLD CASTING", ""))))))))) -> 10KT GOLD CASTING | M18: 0.4166 | N18: 31.1035 | O18: 0.995 | P18: =IF(metal_type[[#This Row],[metal]]="GOLD",Sheet1!$O$12,IF(metal_type[[#This Row],[metal]]="PLATINUM",Sheet1!$O$13,IF(metal_type[[#This Row],[metal]]="SILVER",Sheet1!$O$14,IF(metal_type[[#This Row],[metal]]="SILVER - 925",Sheet1!$O$14,"")))) -> 0 | Q18: 0.4166 | R18: =(metal_type[[#This Row],[metal_rate]]/metal_type[[#This Row],[gram_per_ounce]])*metal_type[[#This Row],[rate_purity]] -> 0
B19: =portal_vendor_code[[#This Row],[Diaspark]]&portal_vendor_code[[#This Row],[Vendor code ]] -> LGSD-UDK024 | C19: LG | D19: SD-UDK024 | E19: 5 | H19: 14KT | J19: 14KT | K19: GOLD | L19: =IF(metal_type[[#This Row],[metal]]="SILVER", "STERLING SILVER CASTING", IF(metal_type[[#This Row],[metal]]="SILVER - 925", "STERLING SILVER CASTING", IF(metal_type[[#This Row],[metal]]="PLATINUM", "950 PLATINUM CASTING", IF(metal_type[[#This Row],[metal_type]]="9KT", "9KT GOLD CASTING", IF(metal_type[[#This Row],[metal_type]]="10KT", "10KT GOLD CASTING", IF(metal_type[[#This Row],[metal_type]]="14KT", "14KT GOLD CASTING", IF(metal_type[[#This Row],[metal_type]]="18KT", "18KT GOLD CASTING", IF(metal_type[[#This Row],[metal_type]]="22KT", "22KT GOLD CASTING", IF(metal_type[[#This Row],[metal_type]]="24KT", "GOLD CASTING", ""))))))))) -> 14KT GOLD CASTING | M19: 0.5833 | N19: 31.1035 | O19: 0.995 | P19: =IF(metal_type[[#This Row],[metal]]="GOLD",Sheet1!$O$12,IF(metal_type[[#This Row],[metal]]="PLATINUM",Sheet1!$O$13,IF(metal_type[[#This Row],[metal]]="SILVER",Sheet1!$O$14,IF(metal_type[[#This Row],[metal]]="SILVER - 925",Sheet1!$O$14,"")))) -> 0 | Q19: 0.5833 | R19: =(metal_type[[#This Row],[metal_rate]]/metal_type[[#This Row],[gram_per_ounce]])*metal_type[[#This Row],[rate_purity]] -> 0
B20: =portal_vendor_code[[#This Row],[Diaspark]]&portal_vendor_code[[#This Row],[Vendor code ]] -> CPCP-S00106 | C20: CP | D20: CP-S00106 | E20: 6 | H20: 18KT | J20: 18KT | K20: GOLD | L20: =IF(metal_type[[#This Row],[metal]]="SILVER", "STERLING SILVER CASTING", IF(metal_type[[#This Row],[metal]]="SILVER - 925", "STERLING SILVER CASTING", IF(metal_type[[#This Row],[metal]]="PLATINUM", "950 PLATINUM CASTING", IF(metal_type[[#This Row],[metal_type]]="9KT", "9KT GOLD CASTING", IF(metal_type[[#This Row],[metal_type]]="10KT", "10KT GOLD CASTING", IF(metal_type[[#This Row],[metal_type]]="14KT", "14KT GOLD CASTING", IF(metal_type[[#This Row],[metal_type]]="18KT", "18KT GOLD CASTING", IF(metal_type[[#This Row],[metal_type]]="22KT", "22KT GOLD CASTING", IF(metal_type[[#This Row],[metal_type]]="24KT", "GOLD CASTING", ""))))))))) -> 18KT GOLD CASTING | M20: 0.75 | N20: 31.1035 | O20: 0.995 | P20: =IF(metal_type[[#This Row],[metal]]="GOLD",Sheet1!$O$12,IF(metal_type[[#This Row],[metal]]="PLATINUM",Sheet1!$O$13,IF(metal_type[[#This Row],[metal]]="SILVER",Sheet1!$O$14,IF(metal_type[[#This Row],[metal]]="SILVER - 925",Sheet1!$O$14,"")))) -> 0 | Q20: 0.75 | R20: =(metal_type[[#This Row],[metal_rate]]/metal_type[[#This Row],[gram_per_ounce]])*metal_type[[#This Row],[rate_purity]] -> 0
B21: =portal_vendor_code[[#This Row],[Diaspark]]&portal_vendor_code[[#This Row],[Vendor code ]] -> KSDS137 | C21: KSD | D21: S137 | E21: 6 | H21: 22KT | J21: 22KT | K21: GOLD | L21: =IF(metal_type[[#This Row],[metal]]="SILVER", "STERLING SILVER CASTING", IF(metal_type[[#This Row],[metal]]="SILVER - 925", "STERLING SILVER CASTING", IF(metal_type[[#This Row],[metal]]="PLATINUM", "950 PLATINUM CASTING", IF(metal_type[[#This Row],[metal_type]]="9KT", "9KT GOLD CASTING", IF(metal_type[[#This Row],[metal_type]]="10KT", "10KT GOLD CASTING", IF(metal_type[[#This Row],[metal_type]]="14KT", "14KT GOLD CASTING", IF(metal_type[[#This Row],[metal_type]]="18KT", "18KT GOLD CASTING", IF(metal_type[[#This Row],[metal_type]]="22KT", "22KT GOLD CASTING", IF(metal_type[[#This Row],[metal_type]]="24KT", "GOLD CASTING", ""))))))))) -> 22KT GOLD CASTING | M21: 0.9166 | N21: 31.1035 | O21: 0.995 | P21: =IF(metal_type[[#This Row],[metal]]="GOLD",Sheet1!$O$12,IF(metal_type[[#This Row],[metal]]="PLATINUM",Sheet1!$O$13,IF(metal_type[[#This Row],[metal]]="SILVER",Sheet1!$O$14,IF(metal_type[[#This Row],[metal]]="SILVER - 925",Sheet1!$O$14,"")))) -> 0 | Q21: 0.9166 | R21: =(metal_type[[#This Row],[metal_rate]]/metal_type[[#This Row],[gram_per_ounce]])*metal_type[[#This Row],[rate_purity]] -> 0
B22: =portal_vendor_code[[#This Row],[Diaspark]]&portal_vendor_code[[#This Row],[Vendor code ]] -> LGLG-S014 | C22: LG | D22: LG-S014 | E22: 6 | H22: PLATINUM | J22: 24KT | K22: GOLD | L22: =IF(metal_type[[#This Row],[metal]]="SILVER", "STERLING SILVER CASTING", IF(metal_type[[#This Row],[metal]]="SILVER - 925", "STERLING SILVER CASTING", IF(metal_type[[#This Row],[metal]]="PLATINUM", "950 PLATINUM CASTING", IF(metal_type[[#This Row],[metal_type]]="9KT", "9KT GOLD CASTING", IF(metal_type[[#This Row],[metal_type]]="10KT", "10KT GOLD CASTING", IF(metal_type[[#This Row],[metal_type]]="14KT", "14KT GOLD CASTING", IF(metal_type[[#This Row],[metal_type]]="18KT", "18KT GOLD CASTING", IF(metal_type[[#This Row],[metal_type]]="22KT", "22KT GOLD CASTING", IF(metal_type[[#This Row],[metal_type]]="24KT", "GOLD CASTING", ""))))))))) -> GOLD CASTING | M22: 1 | N22: 31.1035 | O22: 0.995 | P22: =IF(metal_type[[#This Row],[metal]]="GOLD",Sheet1!$O$12,IF(metal_type[[#This Row],[metal]]="PLATINUM",Sheet1!$O$13,IF(metal_type[[#This Row],[metal]]="SILVER",Sheet1!$O$14,IF(metal_type[[#This Row],[metal]]="SILVER - 925",Sheet1!$O$14,"")))) -> 0 | Q22: 1 | R22: =(metal_type[[#This Row],[metal_rate]]/metal_type[[#This Row],[gram_per_ounce]])*metal_type[[#This Row],[rate_purity]] -> 0
B23: =portal_vendor_code[[#This Row],[Diaspark]]&portal_vendor_code[[#This Row],[Vendor code ]] -> CPCP-UJ00101 | C23: CP | D23: CP-UJ00101 | E23: 7 | H23: SILVER | J23: 950 PLAT | K23: PLATINUM | L23: =IF(metal_type[[#This Row],[metal]]="SILVER", "STERLING SILVER CASTING", IF(metal_type[[#This Row],[metal]]="SILVER - 925", "STERLING SILVER CASTING", IF(metal_type[[#This Row],[metal]]="PLATINUM", "950 PLATINUM CASTING", IF(metal_type[[#This Row],[metal_type]]="9KT", "9KT GOLD CASTING", IF(metal_type[[#This Row],[metal_type]]="10KT", "10KT GOLD CASTING", IF(metal_type[[#This Row],[metal_type]]="14KT", "14KT GOLD CASTING", IF(metal_type[[#This Row],[metal_type]]="18KT", "18KT GOLD CASTING", IF(metal_type[[#This Row],[metal_type]]="22KT", "22KT GOLD CASTING", IF(metal_type[[#This Row],[metal_type]]="24KT", "GOLD CASTING", ""))))))))) -> 950 PLATINUM CASTING | M23: 0.95 | N23: 31.1035 | O23: 1 | P23: =IF(metal_type[[#This Row],[metal]]="GOLD",Sheet1!$O$12,IF(metal_type[[#This Row],[metal]]="PLATINUM",Sheet1!$O$13,IF(metal_type[[#This Row],[metal]]="SILVER",Sheet1!$O$14,IF(metal_type[[#This Row],[metal]]="SILVER - 925",Sheet1!$O$14,"")))) -> 0 | Q23: 1 | R23: =(metal_type[[#This Row],[metal_rate]]/metal_type[[#This Row],[gram_per_ounce]])*metal_type[[#This Row],[rate_purity]] -> 0
B24: =portal_vendor_code[[#This Row],[Diaspark]]&portal_vendor_code[[#This Row],[Vendor code ]] -> KSDU031 | C24: KSD | D24: U031 | E24: 7 | H24: SILVER - 925 | J24: 950 PLATINUM | K24: PLATINUM | L24: =IF(metal_type[[#This Row],[metal]]="SILVER", "STERLING SILVER CASTING", IF(metal_type[[#This Row],[metal]]="SILVER - 925", "STERLING SILVER CASTING", IF(metal_type[[#This Row],[metal]]="PLATINUM", "950 PLATINUM CASTING", IF(metal_type[[#This Row],[metal_type]]="9KT", "9KT GOLD CASTING", IF(metal_type[[#This Row],[metal_type]]="10KT", "10KT GOLD CASTING", IF(metal_type[[#This Row],[metal_type]]="14KT", "14KT GOLD CASTING", IF(metal_type[[#This Row],[metal_type]]="18KT", "18KT GOLD CASTING", IF(metal_type[[#This Row],[metal_type]]="22KT", "22KT GOLD CASTING", IF(metal_type[[#This Row],[metal_type]]="24KT", "GOLD CASTING", ""))))))))) -> 950 PLATINUM CASTING | M24: 0.95 | N24: 31.1035 | O24: 1 | P24: =IF(metal_type[[#This Row],[metal]]="GOLD",Sheet1!$O$12,IF(metal_type[[#This Row],[metal]]="PLATINUM",Sheet1!$O$13,IF(metal_type[[#This Row],[metal]]="SILVER",Sheet1!$O$14,IF(metal_type[[#This Row],[metal]]="SILVER - 925",Sheet1!$O$14,"")))) -> 0 | Q24: 1 | R24: =(metal_type[[#This Row],[metal_rate]]/metal_type[[#This Row],[gram_per_ounce]])*metal_type[[#This Row],[rate_purity]] -> 0
B25: =portal_vendor_code[[#This Row],[Diaspark]]&portal_vendor_code[[#This Row],[Vendor code ]] -> LGLG-U015 | C25: LG | D25: LG-U015 | E25: 7 | J25: 950 PT | K25: PLATINUM | L25: =IF(metal_type[[#This Row],[metal]]="SILVER", "STERLING SILVER CASTING", IF(metal_type[[#This Row],[metal]]="SILVER - 925", "STERLING SILVER CASTING", IF(metal_type[[#This Row],[metal]]="PLATINUM", "950 PLATINUM CASTING", IF(metal_type[[#This Row],[metal_type]]="9KT", "9KT GOLD CASTING", IF(metal_type[[#This Row],[metal_type]]="10KT", "10KT GOLD CASTING", IF(metal_type[[#This Row],[metal_type]]="14KT", "14KT GOLD CASTING", IF(metal_type[[#This Row],[metal_type]]="18KT", "18KT GOLD CASTING", IF(metal_type[[#This Row],[metal_type]]="22KT", "22KT GOLD CASTING", IF(metal_type[[#This Row],[metal_type]]="24KT", "GOLD CASTING", ""))))))))) -> 950 PLATINUM CASTING | M25: 0.95 | N25: 31.1035 | O25: 1 | P25: =IF(metal_type[[#This Row],[metal]]="GOLD",Sheet1!$O$12,IF(metal_type[[#This Row],[metal]]="PLATINUM",Sheet1!$O$13,IF(metal_type[[#This Row],[metal]]="SILVER",Sheet1!$O$14,IF(metal_type[[#This Row],[metal]]="SILVER - 925",Sheet1!$O$14,"")))) -> 0 | Q25: 1 | R25: =(metal_type[[#This Row],[metal_rate]]/metal_type[[#This Row],[gram_per_ounce]])*metal_type[[#This Row],[rate_purity]] -> 0
J26: PLAT | K26: PLATINUM | L26: =IF(metal_type[[#This Row],[metal]]="SILVER", "STERLING SILVER CASTING", IF(metal_type[[#This Row],[metal]]="SILVER - 925", "STERLING SILVER CASTING", IF(metal_type[[#This Row],[metal]]="PLATINUM", "950 PLATINUM CASTING", IF(metal_type[[#This Row],[metal_type]]="9KT", "9KT GOLD CASTING", IF(metal_type[[#This Row],[metal_type]]="10KT", "10KT GOLD CASTING", IF(metal_type[[#This Row],[metal_type]]="14KT", "14KT GOLD CASTING", IF(metal_type[[#This Row],[metal_type]]="18KT", "18KT GOLD CASTING", IF(metal_type[[#This Row],[metal_type]]="22KT", "22KT GOLD CASTING", IF(metal_type[[#This Row],[metal_type]]="24KT", "GOLD CASTING", ""))))))))) -> 950 PLATINUM CASTING | M26: 0.95 | N26: 31.1035 | O26: 1 | P26: =IF(metal_type[[#This Row],[metal]]="GOLD",Sheet1!$O$12,IF(metal_type[[#This Row],[metal]]="PLATINUM",Sheet1!$O$13,IF(metal_type[[#This Row],[metal]]="SILVER",Sheet1!$O$14,IF(metal_type[[#This Row],[metal]]="SILVER - 925",Sheet1!$O$14,"")))) -> 0 | Q26: 1 | R26: =(metal_type[[#This Row],[metal_rate]]/metal_type[[#This Row],[gram_per_ounce]])*metal_type[[#This Row],[rate_purity]] -> 0
J27: PLAT 950 | K27: PLATINUM | L27: =IF(metal_type[[#This Row],[metal]]="SILVER", "STERLING SILVER CASTING", IF(metal_type[[#This Row],[metal]]="SILVER - 925", "STERLING SILVER CASTING", IF(metal_type[[#This Row],[metal]]="PLATINUM", "950 PLATINUM CASTING", IF(metal_type[[#This Row],[metal_type]]="9KT", "9KT GOLD CASTING", IF(metal_type[[#This Row],[metal_type]]="10KT", "10KT GOLD CASTING", IF(metal_type[[#This Row],[metal_type]]="14KT", "14KT GOLD CASTING", IF(metal_type[[#This Row],[metal_type]]="18KT", "18KT GOLD CASTING", IF(metal_type[[#This Row],[metal_type]]="22KT", "22KT GOLD CASTING", IF(metal_type[[#This Row],[metal_type]]="24KT", "GOLD CASTING", ""))))))))) -> 950 PLATINUM CASTING | M27: 0.95 | N27: 31.1035 | O27: 1 | P27: =IF(metal_type[[#This Row],[metal]]="GOLD",Sheet1!$O$12,IF(metal_type[[#This Row],[metal]]="PLATINUM",Sheet1!$O$13,IF(metal_type[[#This Row],[metal]]="SILVER",Sheet1!$O$14,IF(metal_type[[#This Row],[metal]]="SILVER - 925",Sheet1!$O$14,"")))) -> 0 | Q27: 1 | R27: =(metal_type[[#This Row],[metal_rate]]/metal_type[[#This Row],[gram_per_ounce]])*metal_type[[#This Row],[rate_purity]] -> 0
J28: PLATINUM | K28: PLATINUM | L28: =IF(metal_type[[#This Row],[metal]]="SILVER", "STERLING SILVER CASTING", IF(metal_type[[#This Row],[metal]]="SILVER - 925", "STERLING SILVER CASTING", IF(metal_type[[#This Row],[metal]]="PLATINUM", "950 PLATINUM CASTING", IF(metal_type[[#This Row],[metal_type]]="9KT", "9KT GOLD CASTING", IF(metal_type[[#This Row],[metal_type]]="10KT", "10KT GOLD CASTING", IF(metal_type[[#This Row],[metal_type]]="14KT", "14KT GOLD CASTING", IF(metal_type[[#This Row],[metal_type]]="18KT", "18KT GOLD CASTING", IF(metal_type[[#This Row],[metal_type]]="22KT", "22KT GOLD CASTING", IF(metal_type[[#This Row],[metal_type]]="24KT", "GOLD CASTING", ""))))))))) -> 950 PLATINUM CASTING | M28: 0.95 | N28: 31.1035 | O28: 1 | P28: =IF(metal_type[[#This Row],[metal]]="GOLD",Sheet1!$O$12,IF(metal_type[[#This Row],[metal]]="PLATINUM",Sheet1!$O$13,IF(metal_type[[#This Row],[metal]]="SILVER",Sheet1!$O$14,IF(metal_type[[#This Row],[metal]]="SILVER - 925",Sheet1!$O$14,"")))) -> 0 | Q28: 1 | R28: =(metal_type[[#This Row],[metal_rate]]/metal_type[[#This Row],[gram_per_ounce]])*metal_type[[#This Row],[rate_purity]] -> 0
H29: platinum | J29: PLATINUM 950 | K29: PLATINUM | L29: =IF(metal_type[[#This Row],[metal]]="SILVER", "STERLING SILVER CASTING", IF(metal_type[[#This Row],[metal]]="SILVER - 925", "STERLING SILVER CASTING", IF(metal_type[[#This Row],[metal]]="PLATINUM", "950 PLATINUM CASTING", IF(metal_type[[#This Row],[metal_type]]="9KT", "9KT GOLD CASTING", IF(metal_type[[#This Row],[metal_type]]="10KT", "10KT GOLD CASTING", IF(metal_type[[#This Row],[metal_type]]="14KT", "14KT GOLD CASTING", IF(metal_type[[#This Row],[metal_type]]="18KT", "18KT GOLD CASTING", IF(metal_type[[#This Row],[metal_type]]="22KT", "22KT GOLD CASTING", IF(metal_type[[#This Row],[metal_type]]="24KT", "GOLD CASTING", ""))))))))) -> 950 PLATINUM CASTING | M29: 0.95 | N29: 31.1035 | O29: 1 | P29: =IF(metal_type[[#This Row],[metal]]="GOLD",Sheet1!$O$12,IF(metal_type[[#This Row],[metal]]="PLATINUM",Sheet1!$O$13,IF(metal_type[[#This Row],[metal]]="SILVER",Sheet1!$O$14,IF(metal_type[[#This Row],[metal]]="SILVER - 925",Sheet1!$O$14,"")))) -> 0 | Q29: 1 | R29: =(metal_type[[#This Row],[metal_rate]]/metal_type[[#This Row],[gram_per_ounce]])*metal_type[[#This Row],[rate_purity]] -> 0
H30: 950 PLAT | J30: PT | K30: PLATINUM | L30: =IF(metal_type[[#This Row],[metal]]="SILVER", "STERLING SILVER CASTING", IF(metal_type[[#This Row],[metal]]="SILVER - 925", "STERLING SILVER CASTING", IF(metal_type[[#This Row],[metal]]="PLATINUM", "950 PLATINUM CASTING", IF(metal_type[[#This Row],[metal_type]]="9KT", "9KT GOLD CASTING", IF(metal_type[[#This Row],[metal_type]]="10KT", "10KT GOLD CASTING", IF(metal_type[[#This Row],[metal_type]]="14KT", "14KT GOLD CASTING", IF(metal_type[[#This Row],[metal_type]]="18KT", "18KT GOLD CASTING", IF(metal_type[[#This Row],[metal_type]]="22KT", "22KT GOLD CASTING", IF(metal_type[[#This Row],[metal_type]]="24KT", "GOLD CASTING", ""))))))))) -> 950 PLATINUM CASTING | M30: 0.95 | N30: 31.1035 | O30: 1 | P30: =IF(metal_type[[#This Row],[metal]]="GOLD",Sheet1!$O$12,IF(metal_type[[#This Row],[metal]]="PLATINUM",Sheet1!$O$13,IF(metal_type[[#This Row],[metal]]="SILVER",Sheet1!$O$14,IF(metal_type[[#This Row],[metal]]="SILVER - 925",Sheet1!$O$14,"")))) -> 0 | Q30: 1 | R30: =(metal_type[[#This Row],[metal_rate]]/metal_type[[#This Row],[gram_per_ounce]])*metal_type[[#This Row],[rate_purity]] -> 0
H31: 950 PLATINUM | J31: PT 950 | K31: PLATINUM | L31: =IF(metal_type[[#This Row],[metal]]="SILVER", "STERLING SILVER CASTING", IF(metal_type[[#This Row],[metal]]="SILVER - 925", "STERLING SILVER CASTING", IF(metal_type[[#This Row],[metal]]="PLATINUM", "950 PLATINUM CASTING", IF(metal_type[[#This Row],[metal_type]]="9KT", "9KT GOLD CASTING", IF(metal_type[[#This Row],[metal_type]]="10KT", "10KT GOLD CASTING", IF(metal_type[[#This Row],[metal_type]]="14KT", "14KT GOLD CASTING", IF(metal_type[[#This Row],[metal_type]]="18KT", "18KT GOLD CASTING", IF(metal_type[[#This Row],[metal_type]]="22KT", "22KT GOLD CASTING", IF(metal_type[[#This Row],[metal_type]]="24KT", "GOLD CASTING", ""))))))))) -> 950 PLATINUM CASTING | M31: 0.95 | N31: 31.1035 | O31: 1 | P31: =IF(metal_type[[#This Row],[metal]]="GOLD",Sheet1!$O$12,IF(metal_type[[#This Row],[metal]]="PLATINUM",Sheet1!$O$13,IF(metal_type[[#This Row],[metal]]="SILVER",Sheet1!$O$14,IF(metal_type[[#This Row],[metal]]="SILVER - 925",Sheet1!$O$14,"")))) -> 0 | Q31: 1 | R31: =(metal_type[[#This Row],[metal_rate]]/metal_type[[#This Row],[gram_per_ounce]])*metal_type[[#This Row],[rate_purity]] -> 0
H32: 950 PT | J32: 925 SILV | K32: SILVER | L32: =IF(metal_type[[#This Row],[metal]]="SILVER", "STERLING SILVER CASTING", IF(metal_type[[#This Row],[metal]]="SILVER - 925", "STERLING SILVER CASTING", IF(metal_type[[#This Row],[metal]]="PLATINUM", "950 PLATINUM CASTING", IF(metal_type[[#This Row],[metal_type]]="9KT", "9KT GOLD CASTING", IF(metal_type[[#This Row],[metal_type]]="10KT", "10KT GOLD CASTING", IF(metal_type[[#This Row],[metal_type]]="14KT", "14KT GOLD CASTING", IF(metal_type[[#This Row],[metal_type]]="18KT", "18KT GOLD CASTING", IF(metal_type[[#This Row],[metal_type]]="22KT", "22KT GOLD CASTING", IF(metal_type[[#This Row],[metal_type]]="24KT", "GOLD CASTING", ""))))))))) -> STERLING SILVER CASTING | M32: 0.925 | N32: 31.1035 | O32: 1 | P32: =IF(metal_type[[#This Row],[metal]]="GOLD",Sheet1!$O$12,IF(metal_type[[#This Row],[metal]]="PLATINUM",Sheet1!$O$13,IF(metal_type[[#This Row],[metal]]="SILVER",Sheet1!$O$14,IF(metal_type[[#This Row],[metal]]="SILVER - 925",Sheet1!$O$14,"")))) -> 0 | Q32: 0.925 | R32: =(metal_type[[#This Row],[metal_rate]]/metal_type[[#This Row],[gram_per_ounce]])*metal_type[[#This Row],[rate_purity]] -> 0
H33: PLAT | J33: 925 SILVER | K33: SILVER | L33: =IF(metal_type[[#This Row],[metal]]="SILVER", "STERLING SILVER CASTING", IF(metal_type[[#This Row],[metal]]="SILVER - 925", "STERLING SILVER CASTING", IF(metal_type[[#This Row],[metal]]="PLATINUM", "950 PLATINUM CASTING", IF(metal_type[[#This Row],[metal_type]]="9KT", "9KT GOLD CASTING", IF(metal_type[[#This Row],[metal_type]]="10KT", "10KT GOLD CASTING", IF(metal_type[[#This Row],[metal_type]]="14KT", "14KT GOLD CASTING", IF(metal_type[[#This Row],[metal_type]]="18KT", "18KT GOLD CASTING", IF(metal_type[[#This Row],[metal_type]]="22KT", "22KT GOLD CASTING", IF(metal_type[[#This Row],[metal_type]]="24KT", "GOLD CASTING", ""))))))))) -> STERLING SILVER CASTING | M33: 0.925 | N33: 31.1035 | O33: 1 | P33: =IF(metal_type[[#This Row],[metal]]="GOLD",Sheet1!$O$12,IF(metal_type[[#This Row],[metal]]="PLATINUM",Sheet1!$O$13,IF(metal_type[[#This Row],[metal]]="SILVER",Sheet1!$O$14,IF(metal_type[[#This Row],[metal]]="SILVER - 925",Sheet1!$O$14,"")))) -> 0 | Q33: 0.925 | R33: =(metal_type[[#This Row],[metal_rate]]/metal_type[[#This Row],[gram_per_ounce]])*metal_type[[#This Row],[rate_purity]] -> 0
H34: PLAT 950 | J34: 925 STERLING SILVER | K34: SILVER | L34: =IF(metal_type[[#This Row],[metal]]="SILVER", "STERLING SILVER CASTING", IF(metal_type[[#This Row],[metal]]="SILVER - 925", "STERLING SILVER CASTING", IF(metal_type[[#This Row],[metal]]="PLATINUM", "950 PLATINUM CASTING", IF(metal_type[[#This Row],[metal_type]]="9KT", "9KT GOLD CASTING", IF(metal_type[[#This Row],[metal_type]]="10KT", "10KT GOLD CASTING", IF(metal_type[[#This Row],[metal_type]]="14KT", "14KT GOLD CASTING", IF(metal_type[[#This Row],[metal_type]]="18KT", "18KT GOLD CASTING", IF(metal_type[[#This Row],[metal_type]]="22KT", "22KT GOLD CASTING", IF(metal_type[[#This Row],[metal_type]]="24KT", "GOLD CASTING", ""))))))))) -> STERLING SILVER CASTING | M34: 0.925 | N34: 31.1035 | O34: 1 | P34: =IF(metal_type[[#This Row],[metal]]="GOLD",Sheet1!$O$12,IF(metal_type[[#This Row],[metal]]="PLATINUM",Sheet1!$O$13,IF(metal_type[[#This Row],[metal]]="SILVER",Sheet1!$O$14,IF(metal_type[[#This Row],[metal]]="SILVER - 925",Sheet1!$O$14,"")))) -> 0 | Q34: 0.925 | R34: =(metal_type[[#This Row],[metal_rate]]/metal_type[[#This Row],[gram_per_ounce]])*metal_type[[#This Row],[rate_purity]] -> 0
H35: PLATINUM | J35: SILV | K35: SILVER | L35: =IF(metal_type[[#This Row],[metal]]="SILVER", "STERLING SILVER CASTING", IF(metal_type[[#This Row],[metal]]="SILVER - 925", "STERLING SILVER CASTING", IF(metal_type[[#This Row],[metal]]="PLATINUM", "950 PLATINUM CASTING", IF(metal_type[[#This Row],[metal_type]]="9KT", "9KT GOLD CASTING", IF(metal_type[[#This Row],[metal_type]]="10KT", "10KT GOLD CASTING", IF(metal_type[[#This Row],[metal_type]]="14KT", "14KT GOLD CASTING", IF(metal_type[[#This Row],[metal_type]]="18KT", "18KT GOLD CASTING", IF(metal_type[[#This Row],[metal_type]]="22KT", "22KT GOLD CASTING", IF(metal_type[[#This Row],[metal_type]]="24KT", "GOLD CASTING", ""))))))))) -> STERLING SILVER CASTING | M35: 0.925 | N35: 31.1035 | O35: 1 | P35: =IF(metal_type[[#This Row],[metal]]="GOLD",Sheet1!$O$12,IF(metal_type[[#This Row],[metal]]="PLATINUM",Sheet1!$O$13,IF(metal_type[[#This Row],[metal]]="SILVER",Sheet1!$O$14,IF(metal_type[[#This Row],[metal]]="SILVER - 925",Sheet1!$O$14,"")))) -> 0 | Q35: 0.925 | R35: =(metal_type[[#This Row],[metal_rate]]/metal_type[[#This Row],[gram_per_ounce]])*metal_type[[#This Row],[rate_purity]] -> 0
H36: PLATINUM 950 | J36: SILV 925 | K36: SILVER | L36: =IF(metal_type[[#This Row],[metal]]="SILVER", "STERLING SILVER CASTING", IF(metal_type[[#This Row],[metal]]="SILVER - 925", "STERLING SILVER CASTING", IF(metal_type[[#This Row],[metal]]="PLATINUM", "950 PLATINUM CASTING", IF(metal_type[[#This Row],[metal_type]]="9KT", "9KT GOLD CASTING", IF(metal_type[[#This Row],[metal_type]]="10KT", "10KT GOLD CASTING", IF(metal_type[[#This Row],[metal_type]]="14KT", "14KT GOLD CASTING", IF(metal_type[[#This Row],[metal_type]]="18KT", "18KT GOLD CASTING", IF(metal_type[[#This Row],[metal_type]]="22KT", "22KT GOLD CASTING", IF(metal_type[[#This Row],[metal_type]]="24KT", "GOLD CASTING", ""))))))))) -> STERLING SILVER CASTING | M36: 0.925 | N36: 31.1035 | O36: 1 | P36: =IF(metal_type[[#This Row],[metal]]="GOLD",Sheet1!$O$12,IF(metal_type[[#This Row],[metal]]="PLATINUM",Sheet1!$O$13,IF(metal_type[[#This Row],[metal]]="SILVER",Sheet1!$O$14,IF(metal_type[[#This Row],[metal]]="SILVER - 925",Sheet1!$O$14,"")))) -> 0 | Q36: 0.925 | R36: =(metal_type[[#This Row],[metal_rate]]/metal_type[[#This Row],[gram_per_ounce]])*metal_type[[#This Row],[rate_purity]] -> 0
H37: PT | J37: SILVER | K37: SILVER | L37: =IF(metal_type[[#This Row],[metal]]="SILVER", "STERLING SILVER CASTING", IF(metal_type[[#This Row],[metal]]="SILVER - 925", "STERLING SILVER CASTING", IF(metal_type[[#This Row],[metal]]="PLATINUM", "950 PLATINUM CASTING", IF(metal_type[[#This Row],[metal_type]]="9KT", "9KT GOLD CASTING", IF(metal_type[[#This Row],[metal_type]]="10KT", "10KT GOLD CASTING", IF(metal_type[[#This Row],[metal_type]]="14KT", "14KT GOLD CASTING", IF(metal_type[[#This Row],[metal_type]]="18KT", "18KT GOLD CASTING", IF(metal_type[[#This Row],[metal_type]]="22KT", "22KT GOLD CASTING", IF(metal_type[[#This Row],[metal_type]]="24KT", "GOLD CASTING", ""))))))))) -> STERLING SILVER CASTING | M37: 0.925 | N37: 31.1035 | O37: 1 | P37: =IF(metal_type[[#This Row],[metal]]="GOLD",Sheet1!$O$12,IF(metal_type[[#This Row],[metal]]="PLATINUM",Sheet1!$O$13,IF(metal_type[[#This Row],[metal]]="SILVER",Sheet1!$O$14,IF(metal_type[[#This Row],[metal]]="SILVER - 925",Sheet1!$O$14,"")))) -> 0 | Q37: 0.925 | R37: =(metal_type[[#This Row],[metal_rate]]/metal_type[[#This Row],[gram_per_ounce]])*metal_type[[#This Row],[rate_purity]] -> 0
H38: PT 950 | J38: SILVER 925 | K38: SILVER | L38: =IF(metal_type[[#This Row],[metal]]="SILVER", "STERLING SILVER CASTING", IF(metal_type[[#This Row],[metal]]="SILVER - 925", "STERLING SILVER CASTING", IF(metal_type[[#This Row],[metal]]="PLATINUM", "950 PLATINUM CASTING", IF(metal_type[[#This Row],[metal_type]]="9KT", "9KT GOLD CASTING", IF(metal_type[[#This Row],[metal_type]]="10KT", "10KT GOLD CASTING", IF(metal_type[[#This Row],[metal_type]]="14KT", "14KT GOLD CASTING", IF(metal_type[[#This Row],[metal_type]]="18KT", "18KT GOLD CASTING", IF(metal_type[[#This Row],[metal_type]]="22KT", "22KT GOLD CASTING", IF(metal_type[[#This Row],[metal_type]]="24KT", "GOLD CASTING", ""))))))))) -> STERLING SILVER CASTING | M38: 0.925 | N38: 31.1035 | O38: 1 | P38: =IF(metal_type[[#This Row],[metal]]="GOLD",Sheet1!$O$12,IF(metal_type[[#This Row],[metal]]="PLATINUM",Sheet1!$O$13,IF(metal_type[[#This Row],[metal]]="SILVER",Sheet1!$O$14,IF(metal_type[[#This Row],[metal]]="SILVER - 925",Sheet1!$O$14,"")))) -> 0 | Q38: 0.925 | R38: =(metal_type[[#This Row],[metal_rate]]/metal_type[[#This Row],[gram_per_ounce]])*metal_type[[#This Row],[rate_purity]] -> 0
J39: STERLING SILVER | K39: SILVER | L39: =IF(metal_type[[#This Row],[metal]]="SILVER", "STERLING SILVER CASTING", IF(metal_type[[#This Row],[metal]]="SILVER - 925", "STERLING SILVER CASTING", IF(metal_type[[#This Row],[metal]]="PLATINUM", "950 PLATINUM CASTING", IF(metal_type[[#This Row],[metal_type]]="9KT", "9KT GOLD CASTING", IF(metal_type[[#This Row],[metal_type]]="10KT", "10KT GOLD CASTING", IF(metal_type[[#This Row],[metal_type]]="14KT", "14KT GOLD CASTING", IF(metal_type[[#This Row],[metal_type]]="18KT", "18KT GOLD CASTING", IF(metal_type[[#This Row],[metal_type]]="22KT", "22KT GOLD CASTING", IF(metal_type[[#This Row],[metal_type]]="24KT", "GOLD CASTING", ""))))))))) -> STERLING SILVER CASTING | M39: 0.925 | N39: 31.1035 | O39: 1 | P39: =IF(metal_type[[#This Row],[metal]]="GOLD",Sheet1!$O$12,IF(metal_type[[#This Row],[metal]]="PLATINUM",Sheet1!$O$13,IF(metal_type[[#This Row],[metal]]="SILVER",Sheet1!$O$14,IF(metal_type[[#This Row],[metal]]="SILVER - 925",Sheet1!$O$14,"")))) -> 0 | Q39: 0.925 | R39: =(metal_type[[#This Row],[metal_rate]]/metal_type[[#This Row],[gram_per_ounce]])*metal_type[[#This Row],[rate_purity]] -> 0
J40: STERLING SILVER 925 | K40: SILVER | L40: =IF(metal_type[[#This Row],[metal]]="SILVER", "STERLING SILVER CASTING", IF(metal_type[[#This Row],[metal]]="SILVER - 925", "STERLING SILVER CASTING", IF(metal_type[[#This Row],[metal]]="PLATINUM", "950 PLATINUM CASTING", IF(metal_type[[#This Row],[metal_type]]="9KT", "9KT GOLD CASTING", IF(metal_type[[#This Row],[metal_type]]="10KT", "10KT GOLD CASTING", IF(metal_type[[#This Row],[metal_type]]="14KT", "14KT GOLD CASTING", IF(metal_type[[#This Row],[metal_type]]="18KT", "18KT GOLD CASTING", IF(metal_type[[#This Row],[metal_type]]="22KT", "22KT GOLD CASTING", IF(metal_type[[#This Row],[metal_type]]="24KT", "GOLD CASTING", ""))))))))) -> STERLING SILVER CASTING | M40: 0.925 | N40: 31.1035 | O40: 1 | P40: =IF(metal_type[[#This Row],[metal]]="GOLD",Sheet1!$O$12,IF(metal_type[[#This Row],[metal]]="PLATINUM",Sheet1!$O$13,IF(metal_type[[#This Row],[metal]]="SILVER",Sheet1!$O$14,IF(metal_type[[#This Row],[metal]]="SILVER - 925",Sheet1!$O$14,"")))) -> 0 | Q40: 0.925 | R40: =(metal_type[[#This Row],[metal_rate]]/metal_type[[#This Row],[gram_per_ounce]])*metal_type[[#This Row],[rate_purity]] -> 0
J41: SILVER - 925 | K41: SILVER | L41: =IF(metal_type[[#This Row],[metal]]="SILVER", "STERLING SILVER CASTING", IF(metal_type[[#This Row],[metal]]="SILVER - 925", "STERLING SILVER CASTING", IF(metal_type[[#This Row],[metal]]="PLATINUM", "950 PLATINUM CASTING", IF(metal_type[[#This Row],[metal_type]]="9KT", "9KT GOLD CASTING", IF(metal_type[[#This Row],[metal_type]]="10KT", "10KT GOLD CASTING", IF(metal_type[[#This Row],[metal_type]]="14KT", "14KT GOLD CASTING", IF(metal_type[[#This Row],[metal_type]]="18KT", "18KT GOLD CASTING", IF(metal_type[[#This Row],[metal_type]]="22KT", "22KT GOLD CASTING", IF(metal_type[[#This Row],[metal_type]]="24KT", "GOLD CASTING", ""))))))))) -> STERLING SILVER CASTING | M41: 0.925 | N41: 31.1035 | O41: 1 | P41: =IF(metal_type[[#This Row],[metal]]="GOLD",Sheet1!$O$12,IF(metal_type[[#This Row],[metal]]="PLATINUM",Sheet1!$O$13,IF(metal_type[[#This Row],[metal]]="SILVER",Sheet1!$O$14,IF(metal_type[[#This Row],[metal]]="SILVER - 925",Sheet1!$O$14,"")))) -> 0 | Q41: 0.925 | R41: =(metal_type[[#This Row],[metal_rate]]/metal_type[[#This Row],[gram_per_ounce]])*metal_type[[#This Row],[rate_purity]] -> 0
...

Sheet Sheet1
I1: INVOICE
B2: FROM : | L2: SHIP TO : | R2: FROM :
B3: UNIQUE DESIGNS INC | L3: =IF(COUNTA($E$18:$E$72)=0,"", IF(COUNTIF($E$18:$E$72,E18)=COUNTA($E$18:$E$72), UPPER(E18), "MULTIPLE" ) ) | R3: UNIQUE DESIGNS INC FACTORY
B4: 425 MEADOWLANDS PARKWAY 2ND FLOOR | L4: =IFERROR(IF(INDEX(address[ship_address1],MATCH(Sheet1!$L$3,address[ship_nm],0))="","",INDEX(address[ship_address1],MATCH(Sheet1!$L$3,address[ship_nm],0))),"") | R4: 425 MEADOWLANDS PARKWAY 2ND FLOOR
B5: SECAUCUS, NJ 07094 USA | L5: =IFERROR(IF(INDEX(address[ship_address2],MATCH(Sheet1!$L$3,address[ship_nm],0))="","",INDEX(address[ship_address2],MATCH(Sheet1!$L$3,address[ship_nm],0))),"") | R5: SECAUCUS, NJ 07094 USA
B6: TEL : +1 (212) 575-7701 | L6: =IFERROR(INDEX(address[ship_city],MATCH(Sheet1!$L$3,address[ship_nm],0)) & " " & INDEX(address[ship_zip],MATCH(Sheet1!$L$3,address[ship_nm],0)), "") | R6: TEL : +1 (212) 575-7701
L7: =IFERROR(INDEX(address[ship_state],MATCH(Sheet1!$L$3,address[ship_nm],0)) & ", " & INDEX(address[ship_country],MATCH(Sheet1!$L$3,address[ship_nm],0)),"")
L8: =IFERROR(IF(INDEX(address[ship_phone],MATCH(Sheet1!$L$3,address[ship_nm],0))="","",INDEX(address[ship_phone],MATCH(Sheet1!$L$3,address[ship_nm],0))),"") | R8: UDF INVOICE NO :
F9: INVOICE NO : | R9: UDF INVOICE DATE :
F10: INVOICE DATE :
F11: MODE OF SHIPMENT : | G11: MALCA-AMIT | N11: LABOR RATE PER GRAM | R11: LABOR RATE PER GRAM
F12: COUNTRY OF ORIGIN : | G12: USA | N12: GOLD | R12: GOLD
F13: PAYMENT TERMS : | G13: 15 DAYS | N13: PLATINUM | R13: PLATINUM
N14: SILVER | R14: SILVER
I16: =IF(AND(COUNTIF(I18:I89,"*SILVER*")>0, COUNTIF(I18:I89,"*GOLD*")=0, COUNTIF(I18:I89,"*PLATINUM*")=0), "STERLING SILVER CASTING", IF(AND(COUNTIF(I18:I89,"*PLATINUM*")>0, COUNTIF(I18:I89,"*SILVER*")=0, COUNTIF(I18:I89,"*GOLD*")=0), "950 PLATINUM CASTING", IF(AND(COUNTIF(I18:I89,"*SILVER*")>0, COUNTIF(I18:I89,"*GOLD*")>0, COUNTIF(I18:I89,"*PLATINUM*")>0), "SILVER, GOLD AND PLATINUM CASTING", IF(AND(COUNTIF(I18:I89,"*SILVER*")>0, COUNTIF(I18:I89,"*GOLD*")>0), "SILVER AND GOLD CASTING", IF(AND(COUNTIF(I18:I89,"*SILVER*")>0, COUNTIF(I18:I89,"*PLATINUM*")>0), "SILVER AND PLATINUM CASTING", IF(AND(COUNTIF(I18:I89,"*GOLD*")>0, COUNTIF(I18:I89,"*PLATINUM*")>0), "GOLD AND PLATINUM CASTING", IF(COUNTIF(I18:I89,"*SILVER*")>0, "SILVER CASTING", IF(COUNTIF(I18:I89,"*GOLD*")>0, "GOLD CASTING", IF(COUNTIF(I18:I89,"*PLATINUM*")>0, "PLATINUM CASTING", "")))))))))
B17: LN # | C17: WORK ORDER # | D17: VPO # | E17: VENDOR NAME | F17: STYLE # | G17: VENDOR STYLE # | H17: PRODUCT TYPE | I17: DESCRIPTION | J17: METAL TYPE | K17: TOTAL QUANTITY | L17: TOTAL WT.(GRAM) | M17: TOTAL WT. IN PG(GRAM) | N17: TOTAL METAL VALUE | O17: TOTAL LABOR VALUE | P17: TOTAL VALUE | Q17: PRICE PER GRAM | R17: PRICE PER UNIT | S17: REMARKS
I18: =IFERROR(INDEX(metal_type[description],MATCH(J18,metal_type[metal_type],0)),"") | M18: =IF(OR(J18="",L18=""),"",ROUND(((L18*VLOOKUP(J18,metal_type[],4,0))/VLOOKUP(J18,metal_type[],6,0)),2)) | N18: =IF( OR(J18="", L18=""), "", IF( IFERROR( INDEX( metal_type[metal_rate_per_gram], MATCH(Sheet1!J18, metal_type[metal_type], 0) ), 0 ) = 0, "", L18 * INDEX( metal_type[metal_rate_per_gram], MATCH(Sheet1!J18, metal_type[metal_type], 0) ) ) ) | O18: =IF(OR(L18="",$O$11=""),"",L18*$O$11) | P18: =IF(OR(N18="",O18="",$O$11=""),"",N18+O18) | Q18: =IF(OR(L18="",P18=""),"",ROUND(P18/L18,2)) | R18: =IF(OR(K18="",P18=""),"",ROUND(P18/K18,2))
I19: =IFERROR(INDEX(metal_type[description],MATCH(J19,metal_type[metal_type],0)),"") | M19: =IF(OR(J19="",L19=""),"",ROUND(((L19*VLOOKUP(J19,metal_type[],4,0))/VLOOKUP(J19,metal_type[],6,0)),2)) | N19: =IF( OR(J19="", L19=""), "", IF( IFERROR( INDEX( metal_type[metal_rate_per_gram], MATCH(Sheet1!J19, metal_type[metal_type], 0) ), 0 ) = 0, "", L19 * INDEX( metal_type[metal_rate_per_gram], MATCH(Sheet1!J19, metal_type[metal_type], 0) ) ) ) | O19: =IF(OR(L19="",$O$11=""),"",L19*$O$11) | P19: =IF(OR(N19="",O19="",$O$11=""),"",N19+O19) | Q19: =IF(OR(L19="",P19=""),"",ROUND(P19/L19,2)) | R19: =IF(OR(K19="",P19=""),"",ROUND(P19/K19,2))
I20: =IFERROR(INDEX(metal_type[description],MATCH(J20,metal_type[metal_type],0)),"") | M20: =IF(OR(J20="",L20=""),"",ROUND(((L20*VLOOKUP(J20,metal_type[],4,0))/VLOOKUP(J20,metal_type[],6,0)),2)) | N20: =IF( OR(J20="", L20=""), "", IF( IFERROR( INDEX( metal_type[metal_rate_per_gram], MATCH(Sheet1!J20, metal_type[metal_type], 0) ), 0 ) = 0, "", L20 * INDEX( metal_type[metal_rate_per_gram], MATCH(Sheet1!J20, metal_type[metal_type], 0) ) ) ) | O20: =IF(OR(L20="",$O$11=""),"",L20*$O$11) | P20: =IF(OR(N20="",O20="",$O$11=""),"",N20+O20) | Q20: =IF(OR(L20="",P20=""),"",ROUND(P20/L20,2)) | R20: =IF(OR(K20="",P20=""),"",ROUND(P20/K20,2))
I21: =IFERROR(INDEX(metal_type[description],MATCH(J21,metal_type[metal_type],0)),"") | M21: =IF(OR(J21="",L21=""),"",ROUND(((L21*VLOOKUP(J21,metal_type[],4,0))/VLOOKUP(J21,metal_type[],6,0)),2)) | N21: =IF( OR(J21="", L21=""), "", IF( IFERROR( INDEX( metal_type[metal_rate_per_gram], MATCH(Sheet1!J21, metal_type[metal_type], 0) ), 0 ) = 0, "", L21 * INDEX( metal_type[metal_rate_per_gram], MATCH(Sheet1!J21, metal_type[metal_type], 0) ) ) ) | O21: =IF(OR(L21="",$O$11=""),"",L21*$O$11) | P21: =IF(OR(N21="",O21="",$O$11=""),"",N21+O21) | Q21: =IF(OR(L21="",P21=""),"",ROUND(P21/L21,2)) | R21: =IF(OR(K21="",P21=""),"",ROUND(P21/K21,2))
I22: =IFERROR(INDEX(metal_type[description],MATCH(J22,metal_type[metal_type],0)),"") | M22: =IF(OR(J22="",L22=""),"",ROUND(((L22*VLOOKUP(J22,metal_type[],4,0))/VLOOKUP(J22,metal_type[],6,0)),2)) | N22: =IF( OR(J22="", L22=""), "", IF( IFERROR( INDEX( metal_type[metal_rate_per_gram], MATCH(Sheet1!J22, metal_type[metal_type], 0) ), 0 ) = 0, "", L22 * INDEX( metal_type[metal_rate_per_gram], MATCH(Sheet1!J22, metal_type[metal_type], 0) ) ) ) | O22: =IF(OR(L22="",$O$11=""),"",L22*$O$11) | P22: =IF(OR(N22="",O22="",$O$11=""),"",N22+O22) | Q22: =IF(OR(L22="",P22=""),"",ROUND(P22/L22,2)) | R22: =IF(OR(K22="",P22=""),"",ROUND(P22/K22,2))
I23: =IFERROR(INDEX(metal_type[description],MATCH(J23,metal_type[metal_type],0)),"") | M23: =IF(OR(J23="",L23=""),"",ROUND(((L23*VLOOKUP(J23,metal_type[],4,0))/VLOOKUP(J23,metal_type[],6,0)),2)) | N23: =IF( OR(J23="", L23=""), "", IF( IFERROR( INDEX( metal_type[metal_rate_per_gram], MATCH(Sheet1!J23, metal_type[metal_type], 0) ), 0 ) = 0, "", L23 * INDEX( metal_type[metal_rate_per_gram], MATCH(Sheet1!J23, metal_type[metal_type], 0) ) ) ) | O23: =IF(OR(L23="",$O$11=""),"",L23*$O$11) | P23: =IF(OR(N23="",O23="",$O$11=""),"",N23+O23) | Q23: =IF(OR(L23="",P23=""),"",ROUND(P23/L23,2)) | R23: =IF(OR(K23="",P23=""),"",ROUND(P23/K23,2))
I24: =IFERROR(INDEX(metal_type[description],MATCH(J24,metal_type[metal_type],0)),"") | M24: =IF(OR(J24="",L24=""),"",ROUND(((L24*VLOOKUP(J24,metal_type[],4,0))/VLOOKUP(J24,metal_type[],6,0)),2)) | N24: =IF( OR(J24="", L24=""), "", IF( IFERROR( INDEX( metal_type[metal_rate_per_gram], MATCH(Sheet1!J24, metal_type[metal_type], 0) ), 0 ) = 0, "", L24 * INDEX( metal_type[metal_rate_per_gram], MATCH(Sheet1!J24, metal_type[metal_type], 0) ) ) ) | O24: =IF(OR(L24="",$O$11=""),"",L24*$O$11) | P24: =IF(OR(N24="",O24="",$O$11=""),"",N24+O24) | Q24: =IF(OR(L24="",P24=""),"",ROUND(P24/L24,2)) | R24: =IF(OR(K24="",P24=""),"",ROUND(P24/K24,2))
I25: =IFERROR(INDEX(metal_type[description],MATCH(J25,metal_type[metal_type],0)),"") | M25: =IF(OR(J25="",L25=""),"",ROUND(((L25*VLOOKUP(J25,metal_type[],4,0))/VLOOKUP(J25,metal_type[],6,0)),2)) | N25: =IF( OR(J25="", L25=""), "", IF( IFERROR( INDEX( metal_type[metal_rate_per_gram], MATCH(Sheet1!J25, metal_type[metal_type], 0) ), 0 ) = 0, "", L25 * INDEX( metal_type[metal_rate_per_gram], MATCH(Sheet1!J25, metal_type[metal_type], 0) ) ) ) | O25: =IF(OR(L25="",$O$11=""),"",L25*$O$11) | P25: =IF(OR(N25="",O25="",$O$11=""),"",N25+O25) | Q25: =IF(OR(L25="",P25=""),"",ROUND(P25/L25,2)) | R25: =IF(OR(K25="",P25=""),"",ROUND(P25/K25,2))
I26: =IFERROR(INDEX(metal_type[description],MATCH(J26,metal_type[metal_type],0)),"") | M26: =IF(OR(J26="",L26=""),"",ROUND(((L26*VLOOKUP(J26,metal_type[],4,0))/VLOOKUP(J26,metal_type[],6,0)),2)) | N26: =IF( OR(J26="", L26=""), "", IF( IFERROR( INDEX( metal_type[metal_rate_per_gram], MATCH(Sheet1!J26, metal_type[metal_type], 0) ), 0 ) = 0, "", L26 * INDEX( metal_type[metal_rate_per_gram], MATCH(Sheet1!J26, metal_type[metal_type], 0) ) ) ) | O26: =IF(OR(L26="",$O$11=""),"",L26*$O$11) | P26: =IF(OR(N26="",O26="",$O$11=""),"",N26+O26) | Q26: =IF(OR(L26="",P26=""),"",ROUND(P26/L26,2)) | R26: =IF(OR(K26="",P26=""),"",ROUND(P26/K26,2))
I27: =IFERROR(INDEX(metal_type[description],MATCH(J27,metal_type[metal_type],0)),"") | M27: =IF(OR(J27="",L27=""),"",ROUND(((L27*VLOOKUP(J27,metal_type[],4,0))/VLOOKUP(J27,metal_type[],6,0)),2)) | N27: =IF( OR(J27="", L27=""), "", IF( IFERROR( INDEX( metal_type[metal_rate_per_gram], MATCH(Sheet1!J27, metal_type[metal_type], 0) ), 0 ) = 0, "", L27 * INDEX( metal_type[metal_rate_per_gram], MATCH(Sheet1!J27, metal_type[metal_type], 0) ) ) ) | O27: =IF(OR(L27="",$O$11=""),"",L27*$O$11) | P27: =IF(OR(N27="",O27="",$O$11=""),"",N27+O27) | Q27: =IF(OR(L27="",P27=""),"",ROUND(P27/L27,2)) | R27: =IF(OR(K27="",P27=""),"",ROUND(P27/K27,2))
I28: =IFERROR(INDEX(metal_type[description],MATCH(J28,metal_type[metal_type],0)),"") | M28: =IF(OR(J28="",L28=""),"",ROUND(((L28*VLOOKUP(J28,metal_type[],4,0))/VLOOKUP(J28,metal_type[],6,0)),2)) | N28: =IF( OR(J28="", L28=""), "", IF( IFERROR( INDEX( metal_type[metal_rate_per_gram], MATCH(Sheet1!J28, metal_type[metal_type], 0) ), 0 ) = 0, "", L28 * INDEX( metal_type[metal_rate_per_gram], MATCH(Sheet1!J28, metal_type[metal_type], 0) ) ) ) | O28: =IF(OR(L28="",$O$11=""),"",L28*$O$11) | P28: =IF(OR(N28="",O28="",$O$11=""),"",N28+O28) | Q28: =IF(OR(L28="",P28=""),"",ROUND(P28/L28,2)) | R28: =IF(OR(K28="",P28=""),"",ROUND(P28/K28,2))
I29: =IFERROR(INDEX(metal_type[description],MATCH(J29,metal_type[metal_type],0)),"") | M29: =IF(OR(J29="",L29=""),"",ROUND(((L29*VLOOKUP(J29,metal_type[],4,0))/VLOOKUP(J29,metal_type[],6,0)),2)) | N29: =IF( OR(J29="", L29=""), "", IF( IFERROR( INDEX( metal_type[metal_rate_per_gram], MATCH(Sheet1!J29, metal_type[metal_type], 0) ), 0 ) = 0, "", L29 * INDEX( metal_type[metal_rate_per_gram], MATCH(Sheet1!J29, metal_type[metal_type], 0) ) ) ) | O29: =IF(OR(L29="",$O$11=""),"",L29*$O$11) | P29: =IF(OR(N29="",O29="",$O$11=""),"",N29+O29) | Q29: =IF(OR(L29="",P29=""),"",ROUND(P29/L29,2)) | R29: =IF(OR(K29="",P29=""),"",ROUND(P29/K29,2))
... I72: =IFERROR(INDEX(metal_type[description],MATCH(J72,metal_type[metal_type],0)),"") | M72: =IF(OR(J72="",L72=""),"",ROUND(((L72*VLOOKUP(J72,metal_type[],4,0))/VLOOKUP(J72,metal_type[],6,0)),2)) | N72: =IF( OR(J72="", L72=""), "", IF( IFERROR( INDEX( metal_type[metal_rate_per_gram], MATCH(Sheet1!J72, metal_type[metal_type], 0) ), 0 ) = 0, "", L72 * INDEX( metal_type[metal_rate_per_gram], MATCH(Sheet1!J72, metal_type[metal_type], 0) ) ) ) | O72: =IF(OR(L72="",$O$11=""),"",L72*$O$11) | P72: =IF(OR(N72="",O72="",$O$11=""),"",N72+O72) | Q72: =IF(OR(L72="",P72=""),"",ROUND(P72/L72,2)) | R72: =IF(OR(K72="",P72=""),"",ROUND(P72/K72,2))
B73: TOTAL | K73: =IF(SUM(K18:K72)=0,"",SUM(K18:K72)) | L73: =IF(SUM(L18:L72)=0,"",SUM(L18:L72)) | M73: =IF(SUM(M18:M72)=0,"",SUM(M18:M72)) | N73: =IF(SUM(N18:N72)=0,"",SUM(N18:N72)) | O73: =IF(SUM(O18:O72)=0,"",SUM(O18:O72)) | P73: =IF(SUM(P18:P72)=0,"",SUM(P18:P72))
B74: TOTAL CIF VALUE US $ | P74: =IF(P73="","",P73)
B77: EXPORTED FOR SETTING, POLISHING AND FINISHING | L77: BANK DETAILS
K78: BENEFICIARY NAME: | L78: UNIQUE DESIGNS, INC.
B79: =IF($L$3="","",IF(OR(ISNUMBER(SEARCH("ELEGANT",UPPER($L$3))),ISNUMBER(SEARCH("KAMA",UPPER($L$3)))),"VALUABLE CARGO TO BE DEPOSITED AT DGDCL STRONG ROOM, SEEPZ MUMBAI","")) | K79: BENEFICIARY ADDRESS: | L79: 425 MEADOWLANDS PARKWAY
L80: 2ND FLOOR
B81: =IF($L$3="","",IF(ISNUMBER(SEARCH("ELEGANT",UPPER($L$3))),"THE SELLER WARRANTS THAT THESE PRODUCTS HAVE BEEN SUPPLIED IN COMPLIANCE WITH THE SIGNET RESPONSIBLE SOURCING PROTOCOL (""SRSP"").","")) | L81: SECAUCUS, NJ 07094 USA
K82: DEPOSIT A/C : | L82: 100 168 0936
K83: ROUTING NUMBER: | L83: 021 313 103
K84: SWIFT NUMBER: | L84: CTZIUS33
K85: BANK ADDRESS: | L85: CITIZENS BANK
...
